<?xml version='1.0' encoding='utf-8'?>
<mujoco model="biped_digitigrade">
  <compiler angle="radian" autolimits="true" />
  <worldbody>
    <geom name="ground_plane" type="plane" size="0 0 0.05" rgba="0.2 0.3 0.4 1.0" />
    <light pos="0 0 3" dir="0 0 -1" directional="true" />
    <body name="base" pos="0 0 0.45">
      <freejoint name="root" />
      <inertial pos="0 0 0" mass="3.0" diaginertia="0.05 0.05 0.05" />
      <site name="imu" pos="0 0 0.06" size="0.01" />
      <geom size="0.08 0.06" type="cylinder" rgba="0.2 0.2 0.8 1" />
      <body name="left_hip_yaw_link" pos="0 0.08 0">
        <inertial pos="0 0 -0.015" mass="0.3" diaginertia="0.001 0.001 0.001" />
        <joint name="left_hip_yaw_joint" pos="0 0 0" axis="0 0 1" range="-0.523599 0.523599" actuatorfrcrange="-50 50" damping="2" frictionloss="0.2" armature="0.01" />
        <body name="left_hip_roll_link" pos="0 0 -0.03">
          <inertial pos="0 0 -0.01" mass="0.2" diaginertia="0.0005 0.0005 0.0005" />
          <joint name="left_hip_roll_joint" pos="0 0 0" axis="1 0 0" range="-0.349066 0.349066" actuatorfrcrange="-50 50" damping="2" frictionloss="0.2" armature="0.01" />
          <body name="left_thigh_link" pos="0 0 -0.02">
            <inertial pos="0 0 -0.09" mass="1" diaginertia="0.01 0.01 0.001" />
            <joint name="left_hip_pitch_joint" pos="0 0 0" axis="0 1 0" range="-1.5708 1.5708" actuatorfrcrange="-100 100" damping="2" frictionloss="0.2" armature="0.01" />
            <geom size="0.03 0.09" pos="0 0 -0.09" type="cylinder" rgba="0.6 0.6 0.6 1" />
            <body name="left_shank_link" pos="0 0 -0.18">
              <inertial pos="0 0 -0.1" mass="0.6" diaginertia="0.005 0.005 0.0005" />
              <joint name="left_knee_pitch_joint" pos="0 0 0" axis="0 1 0" range="-2.0944 0" actuatorfrcrange="-100 100" damping="2" frictionloss="0.2" armature="0.01" />
              <geom size="0.025 0.1" pos="0 0 -0.1" type="cylinder" rgba="0.4 0.4 0.4 1" />
              <body name="left_foot_link" pos="0 0 -0.2">
                <inertial pos="0 0 -0.015" mass="0.3" diaginertia="0.001 0.001 0.001" />
                <joint name="left_ankle_pitch_joint" pos="0 0 0" axis="0 1 0" range="-0.785398 2.35619" actuatorfrcrange="-50 50" damping="2" frictionloss="0.2" armature="0.01" />
                <geom size="0.05 0.04 0.015" pos="0 0 -0.015" type="box" rgba="0.1 0.1 0.1 1" name="left_foot" friction="0.8 0.02 0.01" solimp="0.015 1 0.03" condim="6" priority="1" />
              </body>
            </body>
          </body>
        </body>
      </body>
      <body name="right_hip_yaw_link" pos="0 -0.08 0">
        <inertial pos="0 0 -0.015" mass="0.3" diaginertia="0.001 0.001 0.001" />
        <joint name="right_hip_yaw_joint" pos="0 0 0" axis="0 0 1" range="-0.523599 0.523599" actuatorfrcrange="-50 50" damping="2" frictionloss="0.2" armature="0.01" />
        <body name="right_hip_roll_link" pos="0 0 -0.03">
          <inertial pos="0 0 -0.01" mass="0.2" diaginertia="0.0005 0.0005 0.0005" />
          <joint name="right_hip_roll_joint" pos="0 0 0" axis="1 0 0" range="-0.349066 0.349066" actuatorfrcrange="-50 50" damping="2" frictionloss="0.2" armature="0.01" />
          <body name="right_thigh_link" pos="0 0 -0.02">
            <inertial pos="0 0 -0.09" mass="1" diaginertia="0.01 0.01 0.001" />
            <joint name="right_hip_pitch_joint" pos="0 0 0" axis="0 1 0" range="-1.5708 1.5708" actuatorfrcrange="-100 100" damping="2" frictionloss="0.2" armature="0.01" />
            <geom size="0.03 0.09" pos="0 0 -0.09" type="cylinder" rgba="0.6 0.6 0.6 1" />
            <body name="right_shank_link" pos="0 0 -0.18">
              <inertial pos="0 0 -0.1" mass="0.6" diaginertia="0.005 0.005 0.0005" />
              <joint name="right_knee_pitch_joint" pos="0 0 0" axis="0 1 0" range="-2.0944 0" actuatorfrcrange="-100 100" damping="2" frictionloss="0.2" armature="0.01" />
              <geom size="0.025 0.1" pos="0 0 -0.1" type="cylinder" rgba="0.4 0.4 0.4 1" />
              <body name="right_foot_link" pos="0 0 -0.2">
                <inertial pos="0 0 -0.015" mass="0.3" diaginertia="0.001 0.001 0.001" />
                <joint name="right_ankle_pitch_joint" pos="0 0 0" axis="0 1 0" range="-0.785398 2.35619" actuatorfrcrange="-50 50" damping="2" frictionloss="0.2" armature="0.01" />
                <geom size="0.05 0.04 0.015" pos="0 0 -0.015" type="box" rgba="0.1 0.1 0.1 1" name="right_foot" friction="0.8 0.02 0.01" solimp="0.015 1 0.03" condim="6" priority="1" />
              </body>
            </body>
          </body>
        </body>
      </body>
    </body>
  </worldbody>
  <option cone="elliptic" impratio="100" />
  <actuator>
    <motor name="left_hip_yaw" joint="left_hip_yaw_joint" gear="1" ctrlrange="-50.0 50.0" />
    <motor name="left_hip_roll" joint="left_hip_roll_joint" gear="1" ctrlrange="-50.0 50.0" />
    <motor name="left_hip_pitch" joint="left_hip_pitch_joint" gear="1" ctrlrange="-100.0 100.0" />
    <motor name="left_knee_pitch" joint="left_knee_pitch_joint" gear="1" ctrlrange="-100.0 100.0" />
    <motor name="left_ankle_pitch" joint="left_ankle_pitch_joint" gear="1" ctrlrange="-50.0 50.0" />
    <motor name="right_hip_yaw" joint="right_hip_yaw_joint" gear="1" ctrlrange="-50.0 50.0" />
    <motor name="right_hip_roll" joint="right_hip_roll_joint" gear="1" ctrlrange="-50.0 50.0" />
    <motor name="right_hip_pitch" joint="right_hip_pitch_joint" gear="1" ctrlrange="-100.0 100.0" />
    <motor name="right_knee_pitch" joint="right_knee_pitch_joint" gear="1" ctrlrange="-100.0 100.0" />
    <motor name="right_ankle_pitch" joint="right_ankle_pitch_joint" gear="1" ctrlrange="-50.0 50.0" />
  </actuator>
  <keyframe>
    <key name="home" qpos="0 0 0.45 1 0 0 0 0.0 0.0 0.0 -0.52 0.52 0.0 0.0 0.0 -0.52 0.52" ctrl="0.0 0.0 0.0 -0.52 0.52 0.0 0.0 0.0 -0.52 0.52" />
  </keyframe>
  <sensor>
    <gyro site="imu" name="gyro" />
    <accelerometer site="imu" name="accelerometer" />
    <framequat objtype="site" objname="imu" name="orientation" />
  </sensor>
</mujoco>