<?xml version="1.0" ?>
<!-- =================================================================================== -->
<!-- |    This document was autogenerated by xacro from src/biped_description/urdf/biped_digitigrade.urdf.xacro | -->
<!-- |    EDITING THIS FILE BY HAND IS NOT RECOMMENDED                                 | -->
<!-- =================================================================================== -->
<robot name="biped_digitigrade">
  <!-- 
    逆関節（Digitigrade/鳥脚型）二脚ロボット URDF
    
    特徴:
    - 膝が前方に曲がる逆関節構造
    - 片脚5関節 × 2脚（左右対称）
    - 関節構成: 腰ヨー, 股関節ロール, 股関節ピッチ, 膝ピッチ, 足首ピッチ
    - IMUリンク: 胴体上面中央に配置（強化学習・状態推定用）
  -->
  <!-- 足部長さ [m] -->
  <!-- マテリアル定義 -->
  <material name="blue">
    <color rgba="0.2 0.2 0.8 1.0"/>
  </material>
  <material name="gray">
    <color rgba="0.6 0.6 0.6 1.0"/>
  </material>
  <material name="dark_gray">
    <color rgba="0.4 0.4 0.4 1.0"/>
  </material>
  <material name="black">
    <color rgba="0.1 0.1 0.1 1.0"/>
  </material>
  <!-- Base Link (胴体) -->
  <link name="base_link">
    <visual>
      <origin rpy="0 0 0" xyz="0 0 0"/>
      <geometry>
        <cylinder length="0.12" radius="0.08"/>
      </geometry>
      <material name="blue"/>
    </visual>
    <collision>
      <origin rpy="0 0 0" xyz="0 0 0"/>
      <geometry>
        <cylinder length="0.12" radius="0.08"/>
      </geometry>
    </collision>
    <inertial>
      <mass value="3.0"/>
      <origin rpy="0 0 0" xyz="0 0 0"/>
      <inertia ixx="0.05" ixy="0" ixz="0" iyy="0.05" iyz="0" izz="0.05"/>
    </inertial>
  </link>
  <!-- IMU Link -->
  <!-- 
    IMUセンサの取り付け位置を定義するフレーム
    - URDFではリンク+固定ジョイントとして定義（ROS 2標準）
    - MuJoCo変換時にはsiteとして扱われ、gyro/accelerometer等のセンサを配置可能
    - 質量・慣性は無視できる程度の小さい値（シミュレーションに影響しない）
  -->
  <link name="imu_link">
    <visual>
      <origin rpy="0 0 0" xyz="0 0 0"/>
      <geometry>
        <box size="0.02 0.02 0.01"/>
      </geometry>
      <material name="dark_gray"/>
    </visual>
    <inertial>
      <mass value="0.01"/>
      <origin rpy="0 0 0" xyz="0 0 0"/>
      <inertia ixx="1e-6" ixy="0" ixz="0" iyy="1e-6" iyz="0" izz="1e-6"/>
    </inertial>
  </link>
  <joint name="imu_joint" type="fixed">
    <parent link="base_link"/>
    <child link="imu_link"/>
    <!-- IMUは胴体上面中央に配置 -->
    <origin rpy="0 0 0" xyz="0 0 0.06"/>
  </joint>
  <!-- 
      関節命名規則:
      - 左脚 (side=left, reflect=1):  j11, j12, j13, j14, j15
      - 右脚 (side=right, reflect=-1): j21, j22, j23, j24, j25
    -->
  <!-- j11/j21: Hip Yaw Joint (腰ヨー) -->
  <joint name="left_hip_yaw_joint" type="revolute">
    <parent link="base_link"/>
    <child link="left_hip_yaw_link"/>
    <origin rpy="0 0 0" xyz="0 0.08 0"/>
    <axis xyz="0 0 1"/>
    <!-- Z軸回転（ヨー） -->
    <limit effort="50" lower="-0.5235987755982988" upper="0.5235987755982988" velocity="5"/>
    <dynamics damping="0.1" friction="0.1"/>
  </joint>
  <link name="left_hip_yaw_link">
    <visual>
      <origin rpy="0 0 0" xyz="0 0 -0.015"/>
      <geometry>
        <cylinder length="0.03" radius="0.02"/>
      </geometry>
      <material name="gray"/>
    </visual>
    <inertial>
      <mass value="0.3"/>
      <origin rpy="0 0 0" xyz="0 0 -0.015"/>
      <inertia ixx="0.001" ixy="0" ixz="0" iyy="0.001" iyz="0" izz="0.001"/>
    </inertial>
  </link>
  <!-- j12/j22: Hip Roll Joint (股関節ロール) -->
  <joint name="left_hip_roll_joint" type="revolute">
    <parent link="left_hip_yaw_link"/>
    <child link="left_hip_roll_link"/>
    <origin rpy="0 0 0" xyz="0 0 -0.03"/>
    <axis xyz="1 0 0"/>
    <!-- X軸回転（ロール） -->
    <limit effort="50" lower="-0.3490658503988659" upper="0.3490658503988659" velocity="5"/>
    <dynamics damping="0.1" friction="0.1"/>
  </joint>
  <link name="left_hip_roll_link">
    <visual>
      <origin rpy="0 0 0" xyz="0 0 -0.01"/>
      <geometry>
        <cylinder length="0.02" radius="0.015"/>
      </geometry>
      <material name="gray"/>
    </visual>
    <inertial>
      <mass value="0.2"/>
      <origin rpy="0 0 0" xyz="0 0 -0.01"/>
      <inertia ixx="0.0005" ixy="0" ixz="0" iyy="0.0005" iyz="0" izz="0.0005"/>
    </inertial>
  </link>
  <!-- j13/j23: Hip Pitch Joint (股関節ピッチ) -->
  <joint name="left_hip_pitch_joint" type="revolute">
    <parent link="left_hip_roll_link"/>
    <child link="left_thigh_link"/>
    <origin rpy="0 0 0" xyz="0 0 -0.02"/>
    <axis xyz="0 1 0"/>
    <!-- Y軸回転（ピッチ） -->
    <limit effort="100" lower="-1.5707963267948966" upper="1.5707963267948966" velocity="10"/>
    <dynamics damping="0.2" friction="0.15"/>
  </joint>
  <link name="left_thigh_link">
    <visual>
      <origin rpy="0 0 0" xyz="0 0 -0.09"/>
      <geometry>
        <cylinder length="0.18" radius="0.03"/>
      </geometry>
      <material name="gray"/>
    </visual>
    <collision>
      <origin rpy="0 0 0" xyz="0 0 -0.09"/>
      <geometry>
        <cylinder length="0.18" radius="0.03"/>
      </geometry>
    </collision>
    <inertial>
      <mass value="1.0"/>
      <origin rpy="0 0 0" xyz="0 0 -0.09"/>
      <inertia ixx="0.01" ixy="0" ixz="0" iyy="0.01" iyz="0" izz="0.001"/>
    </inertial>
  </link>
  <!-- j14/j24: Knee Pitch Joint (膝ピッチ) - 逆関節：前方に曲がる -->
  <joint name="left_knee_pitch_joint" type="revolute">
    <parent link="left_thigh_link"/>
    <child link="left_shank_link"/>
    <origin rpy="0 0 0" xyz="0 0 -0.18"/>
    <axis xyz="0 1 0"/>
    <!-- Y軸回転（ピッチ） -->
    <!-- 逆関節: 負の角度で前方に曲がる -->
    <limit effort="100" lower="-2.0943951023931953" upper="0.0" velocity="10"/>
    <dynamics damping="0.2" friction="0.15"/>
  </joint>
  <link name="left_shank_link">
    <visual>
      <origin rpy="0 0 0" xyz="0 0 -0.1"/>
      <geometry>
        <cylinder length="0.2" radius="0.025"/>
      </geometry>
      <material name="dark_gray"/>
    </visual>
    <collision>
      <origin rpy="0 0 0" xyz="0 0 -0.1"/>
      <geometry>
        <cylinder length="0.2" radius="0.025"/>
      </geometry>
    </collision>
    <inertial>
      <mass value="0.6"/>
      <origin rpy="0 0 0" xyz="0 0 -0.1"/>
      <inertia ixx="0.005" ixy="0" ixz="0" iyy="0.005" iyz="0" izz="0.0005"/>
    </inertial>
  </link>
  <!-- j15/j25: Ankle Pitch Joint (足首ピッチ) -->
  <joint name="left_ankle_pitch_joint" type="revolute">
    <parent link="left_shank_link"/>
    <child link="left_foot_link"/>
    <origin rpy="0 0 0" xyz="0 0 -0.2"/>
    <axis xyz="0 1 0"/>
    <!-- Y軸回転（ピッチ） -->
    <limit effort="50" lower="-0.7853981633974483" upper="2.356194490192345" velocity="10"/>
    <dynamics damping="0.1" friction="0.1"/>
  </joint>
  <link name="left_foot_link">
    <!-- 足首関節が足部の中心に位置する -->
    <!-- 足部は前後に均等に広がる（前方 +X、後方 -X） -->
    <visual>
      <origin rpy="0 0 0" xyz="0 0 -0.015"/>
      <geometry>
        <box size="0.1 0.08 0.03"/>
      </geometry>
      <material name="black"/>
    </visual>
    <collision>
      <origin rpy="0 0 0" xyz="0 0 -0.015"/>
      <geometry>
        <box size="0.1 0.08 0.03"/>
      </geometry>
    </collision>
    <inertial>
      <mass value="0.3"/>
      <origin rpy="0 0 0" xyz="0 0 -0.015"/>
      <inertia ixx="0.001" ixy="0" ixz="0" iyy="0.001" iyz="0" izz="0.001"/>
    </inertial>
  </link>
  <!-- 
      関節命名規則:
      - 左脚 (side=left, reflect=1):  j11, j12, j13, j14, j15
      - 右脚 (side=right, reflect=-1): j21, j22, j23, j24, j25
    -->
  <!-- j11/j21: Hip Yaw Joint (腰ヨー) -->
  <joint name="right_hip_yaw_joint" type="revolute">
    <parent link="base_link"/>
    <child link="right_hip_yaw_link"/>
    <origin rpy="0 0 0" xyz="0 -0.08 0"/>
    <axis xyz="0 0 1"/>
    <!-- Z軸回転（ヨー） -->
    <limit effort="50" lower="-0.5235987755982988" upper="0.5235987755982988" velocity="5"/>
    <dynamics damping="0.1" friction="0.1"/>
  </joint>
  <link name="right_hip_yaw_link">
    <visual>
      <origin rpy="0 0 0" xyz="0 0 -0.015"/>
      <geometry>
        <cylinder length="0.03" radius="0.02"/>
      </geometry>
      <material name="gray"/>
    </visual>
    <inertial>
      <mass value="0.3"/>
      <origin rpy="0 0 0" xyz="0 0 -0.015"/>
      <inertia ixx="0.001" ixy="0" ixz="0" iyy="0.001" iyz="0" izz="0.001"/>
    </inertial>
  </link>
  <!-- j12/j22: Hip Roll Joint (股関節ロール) -->
  <joint name="right_hip_roll_joint" type="revolute">
    <parent link="right_hip_yaw_link"/>
    <child link="right_hip_roll_link"/>
    <origin rpy="0 0 0" xyz="0 0 -0.03"/>
    <axis xyz="1 0 0"/>
    <!-- X軸回転（ロール） -->
    <limit effort="50" lower="-0.3490658503988659" upper="0.3490658503988659" velocity="5"/>
    <dynamics damping="0.1" friction="0.1"/>
  </joint>
  <link name="right_hip_roll_link">
    <visual>
      <origin rpy="0 0 0" xyz="0 0 -0.01"/>
      <geometry>
        <cylinder length="0.02" radius="0.015"/>
      </geometry>
      <material name="gray"/>
    </visual>
    <inertial>
      <mass value="0.2"/>
      <origin rpy="0 0 0" xyz="0 0 -0.01"/>
      <inertia ixx="0.0005" ixy="0" ixz="0" iyy="0.0005" iyz="0" izz="0.0005"/>
    </inertial>
  </link>
  <!-- j13/j23: Hip Pitch Joint (股関節ピッチ) -->
  <joint name="right_hip_pitch_joint" type="revolute">
    <parent link="right_hip_roll_link"/>
    <child link="right_thigh_link"/>
    <origin rpy="0 0 0" xyz="0 0 -0.02"/>
    <axis xyz="0 1 0"/>
    <!-- Y軸回転（ピッチ） -->
    <limit effort="100" lower="-1.5707963267948966" upper="1.5707963267948966" velocity="10"/>
    <dynamics damping="0.2" friction="0.15"/>
  </joint>
  <link name="right_thigh_link">
    <visual>
      <origin rpy="0 0 0" xyz="0 0 -0.09"/>
      <geometry>
        <cylinder length="0.18" radius="0.03"/>
      </geometry>
      <material name="gray"/>
    </visual>
    <collision>
      <origin rpy="0 0 0" xyz="0 0 -0.09"/>
      <geometry>
        <cylinder length="0.18" radius="0.03"/>
      </geometry>
    </collision>
    <inertial>
      <mass value="1.0"/>
      <origin rpy="0 0 0" xyz="0 0 -0.09"/>
      <inertia ixx="0.01" ixy="0" ixz="0" iyy="0.01" iyz="0" izz="0.001"/>
    </inertial>
  </link>
  <!-- j14/j24: Knee Pitch Joint (膝ピッチ) - 逆関節：前方に曲がる -->
  <joint name="right_knee_pitch_joint" type="revolute">
    <parent link="right_thigh_link"/>
    <child link="right_shank_link"/>
    <origin rpy="0 0 0" xyz="0 0 -0.18"/>
    <axis xyz="0 1 0"/>
    <!-- Y軸回転（ピッチ） -->
    <!-- 逆関節: 負の角度で前方に曲がる -->
    <limit effort="100" lower="-2.0943951023931953" upper="0.0" velocity="10"/>
    <dynamics damping="0.2" friction="0.15"/>
  </joint>
  <link name="right_shank_link">
    <visual>
      <origin rpy="0 0 0" xyz="0 0 -0.1"/>
      <geometry>
        <cylinder length="0.2" radius="0.025"/>
      </geometry>
      <material name="dark_gray"/>
    </visual>
    <collision>
      <origin rpy="0 0 0" xyz="0 0 -0.1"/>
      <geometry>
        <cylinder length="0.2" radius="0.025"/>
      </geometry>
    </collision>
    <inertial>
      <mass value="0.6"/>
      <origin rpy="0 0 0" xyz="0 0 -0.1"/>
      <inertia ixx="0.005" ixy="0" ixz="0" iyy="0.005" iyz="0" izz="0.0005"/>
    </inertial>
  </link>
  <!-- j15/j25: Ankle Pitch Joint (足首ピッチ) -->
  <joint name="right_ankle_pitch_joint" type="revolute">
    <parent link="right_shank_link"/>
    <child link="right_foot_link"/>
    <origin rpy="0 0 0" xyz="0 0 -0.2"/>
    <axis xyz="0 1 0"/>
    <!-- Y軸回転（ピッチ） -->
    <limit effort="50" lower="-0.7853981633974483" upper="2.356194490192345" velocity="10"/>
    <dynamics damping="0.1" friction="0.1"/>
  </joint>
  <link name="right_foot_link">
    <!-- 足首関節が足部の中心に位置する -->
    <!-- 足部は前後に均等に広がる（前方 +X、後方 -X） -->
    <visual>
      <origin rpy="0 0 0" xyz="0 0 -0.015"/>
      <geometry>
        <box size="0.1 0.08 0.03"/>
      </geometry>
      <material name="black"/>
    </visual>
    <collision>
      <origin rpy="0 0 0" xyz="0 0 -0.015"/>
      <geometry>
        <box size="0.1 0.08 0.03"/>
      </geometry>
    </collision>
    <inertial>
      <mass value="0.3"/>
      <origin rpy="0 0 0" xyz="0 0 -0.015"/>
      <inertia ixx="0.001" ixy="0" ixz="0" iyy="0.001" iyz="0" izz="0.001"/>
    </inertial>
  </link>
</robot>
