<?xml version="1.0" ?>
<!-- =================================================================================== -->
<!-- |    This document was autogenerated by xacro from src/biped_description/urdf/bsl_droid_simplified_v2.urdf.xacro | -->
<!-- |    EDITING THIS FILE BY HAND IS NOT RECOMMENDED                                 | -->
<!-- =================================================================================== -->
<robot name="bsl_droid_simplified_v2">
  <!--
    BSL-Droid Simplified V2 - 75% torso width variant

    V1からの変更点:
    - torso_width: 0.18 → 0.135 (75%)
    - hip_offset_y: 0.10 → 0.075 (75%)
    - base_link inertia: iyy 0.05→0.038, izz 0.04→0.029 (幅縮小に伴う慣性更新)

    特徴:
    - 膝が後方に曲がる逆関節構造（鳥型）
    - 片脚5関節 × 2脚（左右対称）
    - 関節構成: 股関節ヨー, 股関節ロール, 股関節ピッチ, 膝ピッチ, 足首ピッチ
    - 胴体側面から脚が生える
    - 足裏は半円状（ロール関節を代替）
    - 胴体前方に首、その上に顔（直方体）
    - 顔に2つの円形の目
    - 全高: 約0.9m
  -->
  <!-- 胴体高さ [m] -->
  <!-- 下腿部長さ [m] -->
  <!-- 足首位置: 足後端から中心寄り [m] -->
  <!-- 目の間隔 [m] -->
  <!-- マテリアル定義 -->
  <material name="torso_color">
    <color rgba="0.3 0.5 0.8 1.0"/>
  </material>
  <material name="leg_color">
    <color rgba="0.6 0.6 0.6 1.0"/>
  </material>
  <material name="foot_color">
    <color rgba="0.2 0.2 0.2 1.0"/>
  </material>
  <material name="neck_color">
    <color rgba="0.4 0.6 0.7 1.0"/>
  </material>
  <material name="head_color">
    <color rgba="0.9 0.9 0.9 1.0"/>
  </material>
  <material name="eye_color">
    <color rgba="0.1 0.1 0.1 1.0"/>
  </material>
  <!-- Base Link (胴体) -->
  <link name="base_link">
    <visual>
      <origin rpy="0 0 0" xyz="0 0 0"/>
      <geometry>
        <box size="0.14 0.135 0.16"/>
      </geometry>
      <material name="torso_color"/>
    </visual>
    <collision>
      <origin rpy="0 0 0" xyz="0 0 0"/>
      <geometry>
        <box size="0.14 0.135 0.16"/>
      </geometry>
    </collision>
    <inertial>
      <mass value="3.2"/>
      <origin rpy="0 0 0" xyz="0 0 0"/>
      <inertia ixx="0.05" ixy="0" ixz="0" iyy="0.038" iyz="0" izz="0.029"/>
    </inertial>
  </link>
  <!-- IMU Link -->
  <link name="imu_link">
    <visual>
      <origin rpy="0 0 0" xyz="0 0 0"/>
      <geometry>
        <box size="0.02 0.02 0.01"/>
      </geometry>
      <material name="leg_color"/>
    </visual>
    <inertial>
      <mass value="0.01"/>
      <origin rpy="0 0 0" xyz="0 0 0"/>
      <inertia ixx="1e-6" ixy="0" ixz="0" iyy="1e-6" iyz="0" izz="1e-6"/>
    </inertial>
  </link>
  <joint name="imu_joint" type="fixed">
    <parent link="base_link"/>
    <child link="imu_link"/>
    <!-- IMUは胴体上面中央に配置 -->
    <origin rpy="0 0 0" xyz="0 0 0.085"/>
  </joint>
  <!-- 首 -->
  <link name="neck_link">
    <visual>
      <origin rpy="0 0 0" xyz="0 0 0.0175"/>
      <geometry>
        <cylinder length="0.035" radius="0.018"/>
      </geometry>
      <material name="neck_color"/>
    </visual>
    <collision>
      <origin rpy="0 0 0" xyz="0 0 0.0175"/>
      <geometry>
        <cylinder length="0.035" radius="0.018"/>
      </geometry>
    </collision>
    <inertial>
      <mass value="0.15"/>
      <origin rpy="0 0 0" xyz="0 0 0.0175"/>
      <inertia ixx="0.0003" ixy="0" ixz="0" iyy="0.0003" iyz="0" izz="0.0001"/>
    </inertial>
  </link>
  <joint name="neck_joint" type="fixed">
    <parent link="base_link"/>
    <child link="neck_link"/>
    <!-- 胴体前方・上面から首が生える（X方向を後ろに調整） -->
    <origin rpy="0 0 0" xyz="0.030000000000000006 0 0.08"/>
  </joint>
  <!-- 顔 -->
  <link name="head_link">
    <visual>
      <origin rpy="0 0 0" xyz="0 0 0"/>
      <geometry>
        <box size="0.15 0.19 0.04"/>
      </geometry>
      <material name="head_color"/>
    </visual>
    <collision>
      <origin rpy="0 0 0" xyz="0 0 0"/>
      <geometry>
        <box size="0.15 0.19 0.04"/>
      </geometry>
    </collision>
    <inertial>
      <mass value="0.35"/>
      <origin rpy="0 0 0" xyz="0 0 0"/>
      <inertia ixx="0.0012" ixy="0" ixz="0" iyy="0.0018" iyz="0" izz="0.0015"/>
    </inertial>
  </link>
  <joint name="head_joint" type="fixed">
    <parent link="neck_link"/>
    <child link="head_link"/>
    <origin rpy="0 0 0" xyz="0 0 0.05500000000000001"/>
  </joint>
  <!-- 左目 -->
  <link name="left_eye_link">
    <visual>
      <origin rpy="0 1.5707963267948966 0" xyz="0 0 0"/>
      <geometry>
        <cylinder length="0.005" radius="0.015"/>
      </geometry>
      <material name="eye_color"/>
    </visual>
    <inertial>
      <mass value="0.001"/>
      <origin rpy="0 0 0" xyz="0 0 0"/>
      <inertia ixx="1e-7" ixy="0" ixz="0" iyy="1e-7" iyz="0" izz="1e-7"/>
    </inertial>
  </link>
  <joint name="left_eye_joint" type="fixed">
    <parent link="head_link"/>
    <child link="left_eye_link"/>
    <origin rpy="0 0 0" xyz="0.078 0.06 -0.005"/>
  </joint>
  <!-- 右目 -->
  <link name="right_eye_link">
    <visual>
      <origin rpy="0 1.5707963267948966 0" xyz="0 0 0"/>
      <geometry>
        <cylinder length="0.005" radius="0.015"/>
      </geometry>
      <material name="eye_color"/>
    </visual>
    <inertial>
      <mass value="0.001"/>
      <origin rpy="0 0 0" xyz="0 0 0"/>
      <inertia ixx="1e-7" ixy="0" ixz="0" iyy="1e-7" iyz="0" izz="1e-7"/>
    </inertial>
  </link>
  <joint name="right_eye_joint" type="fixed">
    <parent link="head_link"/>
    <child link="right_eye_link"/>
    <origin rpy="0 0 0" xyz="0.078 -0.06 -0.005"/>
  </joint>
  <!--
      関節命名規則:
      - 左脚 (side=left, reflect=1):  j11, j12, j13, j14, j15
      - 右脚 (side=right, reflect=-1): j21, j22, j23, j24, j25
    -->
  <!-- j11/j21: Hip Yaw Joint (股関節ヨー) -->
  <joint name="left_hip_yaw_joint" type="revolute">
    <parent link="base_link"/>
    <child link="left_hip_yaw_link"/>
    <!-- 胴体側面の中央部から生える: Y方向にオフセット、Z=0（胴体中央高さ） -->
    <origin rpy="0 0 0" xyz="0 0.075 0"/>
    <axis xyz="0 0 1"/>
    <!-- Z軸回転（ヨー） -->
    <limit effort="50" lower="-0.5235987755982988" upper="0.5235987755982988" velocity="5"/>
    <dynamics damping="0.1" friction="0.1"/>
  </joint>
  <link name="left_hip_yaw_link">
    <visual>
      <origin rpy="0 0 0" xyz="0 0 -0.0125"/>
      <geometry>
        <cylinder length="0.025" radius="0.028"/>
      </geometry>
      <material name="leg_color"/>
    </visual>
    <inertial>
      <mass value="0.25"/>
      <origin rpy="0 0 0" xyz="0 0 -0.0125"/>
      <inertia ixx="0.0008" ixy="0" ixz="0" iyy="0.0008" iyz="0" izz="0.0005"/>
    </inertial>
  </link>
  <!-- j12/j22: Hip Roll Joint (股関節ロール) -->
  <joint name="left_hip_roll_joint" type="revolute">
    <parent link="left_hip_yaw_link"/>
    <child link="left_hip_roll_link"/>
    <origin rpy="0 0 0" xyz="0 0 -0.025"/>
    <axis xyz="1 0 0"/>
    <!-- X軸回転（ロール） -->
    <limit effort="50" lower="-0.4363323129985824" upper="0.4363323129985824" velocity="5"/>
    <dynamics damping="0.1" friction="0.1"/>
  </joint>
  <link name="left_hip_roll_link">
    <visual>
      <origin rpy="0 1.5707963267948966 0" xyz="0 0.015 0"/>
      <geometry>
        <cylinder length="0.03" radius="0.022"/>
      </geometry>
      <material name="leg_color"/>
    </visual>
    <inertial>
      <mass value="0.18"/>
      <origin rpy="0 0 0" xyz="0 0.015 0"/>
      <inertia ixx="0.0005" ixy="0" ixz="0" iyy="0.0005" iyz="0" izz="0.0003"/>
    </inertial>
  </link>
  <!-- j13/j23: Hip Pitch Joint (股関節ピッチ) -->
  <joint name="left_hip_pitch_joint" type="revolute">
    <parent link="left_hip_roll_link"/>
    <child link="left_thigh_link"/>
    <origin rpy="0 0 0" xyz="0 0.03 0"/>
    <axis xyz="0 1 0"/>
    <!-- Y軸回転（ピッチ） -->
    <limit effort="100" lower="-2.0943951023931953" upper="1.5707963267948966" velocity="10"/>
    <dynamics damping="0.2" friction="0.15"/>
  </joint>
  <link name="left_thigh_link">
    <visual>
      <origin rpy="0 0 0" xyz="0 0 -0.055"/>
      <geometry>
        <cylinder length="0.11" radius="0.028"/>
      </geometry>
      <material name="leg_color"/>
    </visual>
    <collision>
      <origin rpy="0 0 0" xyz="0 0 -0.055"/>
      <geometry>
        <cylinder length="0.11" radius="0.028"/>
      </geometry>
    </collision>
    <inertial>
      <mass value="0.7"/>
      <origin rpy="0 0 0" xyz="0 0 -0.055"/>
      <inertia ixx="0.005" ixy="0" ixz="0" iyy="0.005" iyz="0" izz="0.0008"/>
    </inertial>
  </link>
  <!-- j14/j24: Knee Pitch Joint (膝ピッチ) - 逆関節：負角度で後方に曲がる -->
  <joint name="left_knee_pitch_joint" type="revolute">
    <parent link="left_thigh_link"/>
    <child link="left_shank_link"/>
    <origin rpy="0 0 0" xyz="0 0 -0.11"/>
    <axis xyz="0 1 0"/>
    <!-- Y軸回転（ピッチ）- 他のピッチ軸と統一 -->
    <!-- 逆関節: 負の角度で後方屈曲（Unitree/ANYmal等と同じ規約） -->
    <limit effort="100" lower="-2.6179938779914944" upper="0.0" velocity="10"/>
    <dynamics damping="0.2" friction="0.15"/>
  </joint>
  <link name="left_shank_link">
    <visual>
      <origin rpy="0 0 0" xyz="0 0 -0.06"/>
      <geometry>
        <cylinder length="0.12" radius="0.023"/>
      </geometry>
      <material name="leg_color"/>
    </visual>
    <collision>
      <origin rpy="0 0 0" xyz="0 0 -0.06"/>
      <geometry>
        <cylinder length="0.12" radius="0.023"/>
      </geometry>
    </collision>
    <inertial>
      <mass value="0.5"/>
      <origin rpy="0 0 0" xyz="0 0 -0.06"/>
      <inertia ixx="0.003" ixy="0" ixz="0" iyy="0.003" iyz="0" izz="0.0005"/>
    </inertial>
  </link>
  <!-- j15/j25: Ankle Pitch Joint (足首ピッチ) -->
  <joint name="left_ankle_pitch_joint" type="revolute">
    <parent link="left_shank_link"/>
    <child link="left_foot_link"/>
    <!-- 足首は足の後端から少し中心寄り -->
    <origin rpy="0 0 0" xyz="0 0 -0.12"/>
    <axis xyz="0 1 0"/>
    <!-- Y軸回転（ピッチ） -->
    <limit effort="50" lower="-1.5707963267948966" upper="1.5707963267948966" velocity="10"/>
    <dynamics damping="0.1" friction="0.1"/>
  </joint>
  <link name="left_foot_link">
    <!-- 足裏は半円状（かまぼこ型） - ロール関節を代替 -->
    <!-- 足首関節位置から後方へ少しオフセット、前方へ伸びる形状 -->
    <visual>
      <!-- メインの足部本体（直方体） -->
      <origin rpy="0 0 0" xyz="0.02 0 -0.0175"/>
      <geometry>
        <box size="0.09 0.06 0.035"/>
      </geometry>
      <material name="foot_color"/>
    </visual>
    <visual>
      <!-- 足裏の半円形状（Y軸方向に円筒を配置） -->
      <origin rpy="0 1.5707963267948966 0" xyz="0.02 0 -0.035"/>
      <geometry>
        <cylinder length="0.09" radius="0.03"/>
      </geometry>
      <material name="foot_color"/>
    </visual>
    <collision>
      <!-- 接地用の半円形状 -->
      <origin rpy="0 1.5707963267948966 0" xyz="0.02 0 -0.035"/>
      <geometry>
        <cylinder length="0.09" radius="0.03"/>
      </geometry>
    </collision>
    <inertial>
      <mass value="0.25"/>
      <origin rpy="0 0 0" xyz="0.02 0 -0.0175"/>
      <inertia ixx="0.0008" ixy="0" ixz="0" iyy="0.0008" iyz="0" izz="0.0006"/>
    </inertial>
  </link>
  <!--
      関節命名規則:
      - 左脚 (side=left, reflect=1):  j11, j12, j13, j14, j15
      - 右脚 (side=right, reflect=-1): j21, j22, j23, j24, j25
    -->
  <!-- j11/j21: Hip Yaw Joint (股関節ヨー) -->
  <joint name="right_hip_yaw_joint" type="revolute">
    <parent link="base_link"/>
    <child link="right_hip_yaw_link"/>
    <!-- 胴体側面の中央部から生える: Y方向にオフセット、Z=0（胴体中央高さ） -->
    <origin rpy="0 0 0" xyz="0 -0.075 0"/>
    <axis xyz="0 0 1"/>
    <!-- Z軸回転（ヨー） -->
    <limit effort="50" lower="-0.5235987755982988" upper="0.5235987755982988" velocity="5"/>
    <dynamics damping="0.1" friction="0.1"/>
  </joint>
  <link name="right_hip_yaw_link">
    <visual>
      <origin rpy="0 0 0" xyz="0 0 -0.0125"/>
      <geometry>
        <cylinder length="0.025" radius="0.028"/>
      </geometry>
      <material name="leg_color"/>
    </visual>
    <inertial>
      <mass value="0.25"/>
      <origin rpy="0 0 0" xyz="0 0 -0.0125"/>
      <inertia ixx="0.0008" ixy="0" ixz="0" iyy="0.0008" iyz="0" izz="0.0005"/>
    </inertial>
  </link>
  <!-- j12/j22: Hip Roll Joint (股関節ロール) -->
  <joint name="right_hip_roll_joint" type="revolute">
    <parent link="right_hip_yaw_link"/>
    <child link="right_hip_roll_link"/>
    <origin rpy="0 0 0" xyz="0 0 -0.025"/>
    <axis xyz="1 0 0"/>
    <!-- X軸回転（ロール） -->
    <limit effort="50" lower="-0.4363323129985824" upper="0.4363323129985824" velocity="5"/>
    <dynamics damping="0.1" friction="0.1"/>
  </joint>
  <link name="right_hip_roll_link">
    <visual>
      <origin rpy="0 1.5707963267948966 0" xyz="0 -0.015 0"/>
      <geometry>
        <cylinder length="0.03" radius="0.022"/>
      </geometry>
      <material name="leg_color"/>
    </visual>
    <inertial>
      <mass value="0.18"/>
      <origin rpy="0 0 0" xyz="0 -0.015 0"/>
      <inertia ixx="0.0005" ixy="0" ixz="0" iyy="0.0005" iyz="0" izz="0.0003"/>
    </inertial>
  </link>
  <!-- j13/j23: Hip Pitch Joint (股関節ピッチ) -->
  <joint name="right_hip_pitch_joint" type="revolute">
    <parent link="right_hip_roll_link"/>
    <child link="right_thigh_link"/>
    <origin rpy="0 0 0" xyz="0 -0.03 0"/>
    <axis xyz="0 1 0"/>
    <!-- Y軸回転（ピッチ） -->
    <limit effort="100" lower="-2.0943951023931953" upper="1.5707963267948966" velocity="10"/>
    <dynamics damping="0.2" friction="0.15"/>
  </joint>
  <link name="right_thigh_link">
    <visual>
      <origin rpy="0 0 0" xyz="0 0 -0.055"/>
      <geometry>
        <cylinder length="0.11" radius="0.028"/>
      </geometry>
      <material name="leg_color"/>
    </visual>
    <collision>
      <origin rpy="0 0 0" xyz="0 0 -0.055"/>
      <geometry>
        <cylinder length="0.11" radius="0.028"/>
      </geometry>
    </collision>
    <inertial>
      <mass value="0.7"/>
      <origin rpy="0 0 0" xyz="0 0 -0.055"/>
      <inertia ixx="0.005" ixy="0" ixz="0" iyy="0.005" iyz="0" izz="0.0008"/>
    </inertial>
  </link>
  <!-- j14/j24: Knee Pitch Joint (膝ピッチ) - 逆関節：負角度で後方に曲がる -->
  <joint name="right_knee_pitch_joint" type="revolute">
    <parent link="right_thigh_link"/>
    <child link="right_shank_link"/>
    <origin rpy="0 0 0" xyz="0 0 -0.11"/>
    <axis xyz="0 1 0"/>
    <!-- Y軸回転（ピッチ）- 他のピッチ軸と統一 -->
    <!-- 逆関節: 負の角度で後方屈曲（Unitree/ANYmal等と同じ規約） -->
    <limit effort="100" lower="-2.6179938779914944" upper="0.0" velocity="10"/>
    <dynamics damping="0.2" friction="0.15"/>
  </joint>
  <link name="right_shank_link">
    <visual>
      <origin rpy="0 0 0" xyz="0 0 -0.06"/>
      <geometry>
        <cylinder length="0.12" radius="0.023"/>
      </geometry>
      <material name="leg_color"/>
    </visual>
    <collision>
      <origin rpy="0 0 0" xyz="0 0 -0.06"/>
      <geometry>
        <cylinder length="0.12" radius="0.023"/>
      </geometry>
    </collision>
    <inertial>
      <mass value="0.5"/>
      <origin rpy="0 0 0" xyz="0 0 -0.06"/>
      <inertia ixx="0.003" ixy="0" ixz="0" iyy="0.003" iyz="0" izz="0.0005"/>
    </inertial>
  </link>
  <!-- j15/j25: Ankle Pitch Joint (足首ピッチ) -->
  <joint name="right_ankle_pitch_joint" type="revolute">
    <parent link="right_shank_link"/>
    <child link="right_foot_link"/>
    <!-- 足首は足の後端から少し中心寄り -->
    <origin rpy="0 0 0" xyz="0 0 -0.12"/>
    <axis xyz="0 1 0"/>
    <!-- Y軸回転（ピッチ） -->
    <limit effort="50" lower="-1.5707963267948966" upper="1.5707963267948966" velocity="10"/>
    <dynamics damping="0.1" friction="0.1"/>
  </joint>
  <link name="right_foot_link">
    <!-- 足裏は半円状（かまぼこ型） - ロール関節を代替 -->
    <!-- 足首関節位置から後方へ少しオフセット、前方へ伸びる形状 -->
    <visual>
      <!-- メインの足部本体（直方体） -->
      <origin rpy="0 0 0" xyz="0.02 0 -0.0175"/>
      <geometry>
        <box size="0.09 0.06 0.035"/>
      </geometry>
      <material name="foot_color"/>
    </visual>
    <visual>
      <!-- 足裏の半円形状（Y軸方向に円筒を配置） -->
      <origin rpy="0 1.5707963267948966 0" xyz="0.02 0 -0.035"/>
      <geometry>
        <cylinder length="0.09" radius="0.03"/>
      </geometry>
      <material name="foot_color"/>
    </visual>
    <collision>
      <!-- 接地用の半円形状 -->
      <origin rpy="0 1.5707963267948966 0" xyz="0.02 0 -0.035"/>
      <geometry>
        <cylinder length="0.09" radius="0.03"/>
      </geometry>
    </collision>
    <inertial>
      <mass value="0.25"/>
      <origin rpy="0 0 0" xyz="0.02 0 -0.0175"/>
      <inertia ixx="0.0008" ixy="0" ixz="0" iyy="0.0008" iyz="0" izz="0.0006"/>
    </inertial>
  </link>
</robot>
